Workbook
Name DayRails: StartDateWindow+ROW('Project timeline'!$1:$9)-1
Name GridCalc: IFERROR(calcs!$A1/SUMPRODUCT( (Activities[Id]=calcs!$C1)*(Activities[Start]<=calcs!A$31)*((Activities[End]>=calcs!A$31)+(LEN(Activities[End])=0)*(Activities[Start]=calcs!A$31)) ),NA())
Name GridCalc: IFERROR(calcs!$A1/SUMPRODUCT( (Activities[Id]=calcs!$C1)*(Activities[Start]<=calcs!A$31)*((Activities[End]>=calcs!A$31)+(LEN(Activities[End])=0)*(Activities[Start]=calcs!A$31)) ),NA())
Name RowTitleRegion1..D3: 'Project timeline'!$D$2
Name StartDate: calcs!$D$28
Name StartDateWindow: calcs!$D$25
Name Title1: Activities[[#Headers],[Deadline ]]
Name Title1: Activities[[#Headers],[Deadline ]]
Name WindowDays: calcs!$D$29
Name WindowOffset: calcs!$D$26

Sheet Project timeline
C1: T2 Project Timeline
D2: Start Date | F2: 45992
C4: Chart showing project activities with a scrollable timeline is in this cell.
B6: Id | C6: Deadline | D6: Start | E6: End | F6: Notes | G6: Done?
B7: =ROW(B7)-calcs!$D$5 -> -15 | C7: Project Start | D7: 45992
B8: =ROW(B8)-calcs!$D$5 -> -14 | C8: STAGE ONE | D8: 45992
B9: =ROW(B9)-calcs!$D$5 -> -13 | C9: Initial project proposal "lite" due | D9: 45992 | F9: 11:00:00 PM on Canvas | G9: TRUE
B10: =ROW(B10)-calcs!$D$5 -> -12 | C10: Time to consult with faculty | D10: 45995 | F10: 11:30:00 AM -12:30:00 PM | G10: TRUE
B11: =ROW(B11)-calcs!$D$5 -> -11 | C11: Initial full project proposal due | D11: 46028 | F11: 11:00:00 PM on Canvas | G11: TRUE
B12: =ROW(B12)-calcs!$D$5 -> -10 | C12: STAGE TWO | D12: 46041
B13: =ROW(B13)-calcs!$D$5 -> -9 | C13: Informal 1 on 1 meeting with mentor | D13: 46041 | E13: 46045 | F13: Self-scheduled, requireed | G13: TRUE
B14: =ROW(B14)-calcs!$D$5 -> -8 | C14: Formal round table meeting with mentor | D14: 46048 | E14: 46052 | F14: Mentor will schedule, required | G14: TRUE
B15: =ROW(B15)-calcs!$D$5 -> -7 | C15: Submission of one-page update | D15: 46061 | F15: 11:00:00 PM on Canvas | G15: TRUE
B16: =ROW(B16)-calcs!$D$5 -> -6 | C16: Informal 1 on 1 meeting with mentor | D16: 46063 | E16: 46067 | F16: Self-scheduled, requireed | G16: TRUE
B17: =ROW(B17)-calcs!$D$5 -> -5 | C17: Methods and data analysis due | D17: =D16+15 -> 46078 | E17: =Activities[[#This Row],[Start]]+5 -> 46083 | F17: 11:00:00 PM on Canvas | G17: TRUE
B18: =ROW(B18)-calcs!$D$5 -> -4 | C18: Formal round table meeting with mentor | D18: 46076 | E18: 46080 | F18: Mentor will schedule, required | G18: TRUE
B19: =ROW(B19)-calcs!$D$5 -> -3 | C19: STAGE THREE | D19: 46076
B20: =ROW(B20)-calcs!$D$5 -> -2 | C20: Initial report due for peer review | D20: 46095 | F20: 11:00:00 PM on ComPAIR | G20: FALSE
B21: =ROW(B21)-calcs!$D$5 -> -1 | C21: Peer review feedback due | F21: 11:00:00 PM on ComPAIR | G21: FALSE
B22: =ROW(B22)-calcs!$D$5 -> 0 | C22: Conference abstract due | D22: 46101 | F22: 11:00:00 PM on ComPAIR | G22: FALSE
B23: =ROW(B23)-calcs!$D$5 -> 1 | C23: Check in with mentor | D23: 46097 | E23: 46101 | F23: Self-scheduled, requireed | G23: FALSE
B24: =ROW(B24)-calcs!$D$5 -> 2 | C24: STAGE FOUR | D24: 46108
B25: =ROW(B25)-calcs!$D$5 -> 3 | C25: T2 Conference | D25: 46108 | E25: 46110 | F25: Loon Lake | G25: FALSE
B26: =ROW(B26)-calcs!$D$5 -> 4 | C26: Final check-in with mentor | D26: 46111 | E26: 46114 | F26: Self-scheduled, requireed | G26: FALSE
B27: =ROW(B27)-calcs!$D$5 -> 5 | C27: Final repor due (with lettter to the editor) | D27: 46119 | F27: 11:00:00 PM on Canvas | G27: FALSE
B28: =ROW(B28)-calcs!$D$5 -> 6 | C28: Project End | D28: 46119

Sheet Tasks
B1: TASK LIST
B2: TASKS | C2: START DATE | D2: DUE DATE | E2: % COMPLETE | F2: DONE | G2: NOTES | H2: ASSIGNED TO
B3: Chemicals from Guillaume | C3: N/A | D3: 45995 | E3: 1 | F3: =--(Tasks[[#This Row],[% COMPLETE]]>=1) -> 1 | G3: KOH(s) in Oli cabinets | H3: Both
B4: Meet with Dr. Harley | C4: 46008 | D4: 46008 | E4: 1 | F4: =--(Tasks[[#This Row],[% COMPLETE]]>=1) -> 1 | G4: 3:00pm in BRC 6017 | H4: Both
B5: Meet with Julie | C5: 46028 | D5: 46028 | E5: 1 | F5: =--(Tasks[[#This Row],[% COMPLETE]]>=1) -> 1 | G5: 12:30 in Oliver Room | H5: Both
B6: Initial field work with Julie | C6: 46033 | D6: 46033 | E6: 1 | F6: =--(Tasks[[#This Row],[% COMPLETE]]>=1) -> 1 | G6: Meet 5:15 outside IKB facing Nest/LIFE, bring headlamp/flashlight | H6: Both
B7: Talk to Nic, Julie, Carl from Harley Lab | C7: 46008 | D7: 46042 | E7: 1 | F7: =--(Tasks[[#This Row],[% COMPLETE]]>=1) -> 1 | H7: Both
B8: RD1 Pilot | C8: 46010 | D8: 46050 | E8: 1 | F8: =--(Tasks[[#This Row],[% COMPLETE]]>=1) -> 1 | G8: A smaller round to test/optimize processes | H8: Both
B9: Wreck Beach Collection | C9: 46052 | D9: 46058 | E9: 1 | F9: =--(Tasks[[#This Row],[% COMPLETE]]>=1) -> 1
B10: WB Dissection | C10: 46055 | D10: 46059 | E10: 1 | F10: =--(Tasks[[#This Row],[% COMPLETE]]>=1) -> 1 | G10: Placeholder date until scheduled
B11: Kits Beach Collection | C11: 46052 | D11: 46060 | E11: 1 | F11: =--(Tasks[[#This Row],[% COMPLETE]]>=1) -> 1 | G11: Placeholder date until scheduled
B12: Progress Report | C12: 46052 | D12: 46061 | E12: 1 | F12: =--(Tasks[[#This Row],[% COMPLETE]]>=1) -> 1
B13: WB Digestion | C13: 46057 | D13: 46061 | E13: 1 | F13: =--(Tasks[[#This Row],[% COMPLETE]]>=1) -> 1
B14: WB Drying | C14: 46058 | D14: 46064 | E14: 1 | F14: =--(Tasks[[#This Row],[% COMPLETE]]>=1) -> 1 | G14: need filter paper
B15: WB Analysis | C15: 46057 | D15: 46065 | E15: 1 | F15: =--(Tasks[[#This Row],[% COMPLETE]]>=1) -> 1
B16: KB Dissection | C16: 46057 | D16: 46065 | E16: 1 | F16: =--(Tasks[[#This Row],[% COMPLETE]]>=1) -> 1
B17: KB Digestion | C17: 46057 | D17: 46067 | E17: 1 | F17: =--(Tasks[[#This Row],[% COMPLETE]]>=1) -> 1
B18: English Bay Collection | C18: 46052 | D18: 46070 | E18: 1 | F18: =--(Tasks[[#This Row],[% COMPLETE]]>=1) -> 1
B19: Lions Bay Collection | C19: 46052 | D19: 46075 | E19: 1 | F19: =--(Tasks[[#This Row],[% COMPLETE]]>=1) -> 1 | G19: Placeholder date until scheduled
B20: Brunswick Beach Collection | C20: 46052 | D20: 46075 | E20: 1 | F20: =--(Tasks[[#This Row],[% COMPLETE]]>=1) -> 1 | G20: Placeholder date until scheduled
B21: Porteau Cove Collection | C21: 46052 | D21: =D19 -> 46075 | E21: 1 | F21: =--(Tasks[[#This Row],[% COMPLETE]]>=1) -> 1 | G21: Placeholder date until scheduled
B22: SB Dissection | C22: 46057 | D22: 46076 | E22: 1 | F22: =--(Tasks[[#This Row],[% COMPLETE]]>=1) -> 1 | G22: Placeholder date until scheduled
B23: BB Dissection | C23: 46057 | D23: 46076 | E23: 1 | F23: =--(Tasks[[#This Row],[% COMPLETE]]>=1) -> 1 | G23: Placeholder date until scheduled
B24: EB Dissection | C24: 46057 | D24: 46077 | E24: 1 | F24: =--(Tasks[[#This Row],[% COMPLETE]]>=1) -> 1
B25: EB Digestion | C25: 46057 | D25: 46077 | E25: 1 | F25: =--(Tasks[[#This Row],[% COMPLETE]]>=1) -> 1
B26: Methods Draft and Data Analysis | C26: 46052 | D26: 46078 | E26: 1 | F26: =--(Tasks[[#This Row],[% COMPLETE]]>=1) -> 1
B27: PC Dissection | C27: 46057 | D27: 46080 | E27: 1 | F27: =--(Tasks[[#This Row],[% COMPLETE]]>=1) -> 1
B28: KB Analysis | C28: 46057 | D28: 46081 | E28: 1 | F28: =--(Tasks[[#This Row],[% COMPLETE]]>=1) -> 1
B29: EB Analysis | C29: 46057 | D29: 46081 | E29: 1 | F29: =--(Tasks[[#This Row],[% COMPLETE]]>=1) -> 1
B30: RD 2&3 Data Analysis | C30: 46052 | D30: 46081 | E30: 1 | F30: =--(Tasks[[#This Row],[% COMPLETE]]>=1) -> 1
B31: LB Digestion | C31: 46057 | D31: 46081 | E31: 1 | F31: =--(Tasks[[#This Row],[% COMPLETE]]>=1) -> 1 | G31: Placeholder date until scheduled
B32: BB Digestion | C32: 46057 | D32: 46081 | E32: 1 | F32: =--(Tasks[[#This Row],[% COMPLETE]]>=1) -> 1 | G32: Placeholder date until scheduled
B33: PC Digestion | C33: 46057 | D33: 46081 | E33: 1 | F33: =--(Tasks[[#This Row],[% COMPLETE]]>=1) -> 1 | G33: Placeholder date until scheduled
B34: BB Analysis | C34: 46057 | D34: 46089 | E34: 1 | F34: =--(Tasks[[#This Row],[% COMPLETE]]>=1) -> 1 | G34: Placeholder date until scheduled
B35: PC Analysis | C35: 46057 | D35: 46094 | E35: 0 | F35: =--(Tasks[[#This Row],[% COMPLETE]]>=1) -> 0 | G35: Placeholder date until scheduled
B36: RD3 Visual Analysis | C36: 45687 | D36: 46094 | E36: 0 | F36: =--(Tasks[[#This Row],[% COMPLETE]]>=1) -> 0 | G36: Non urban crabs (all)
B37: LB Analysis | C37: 46057 | D37: 46094 | E37: 0 | F37: =--(Tasks[[#This Row],[% COMPLETE]]>=1) -> 0 | G37: Placeholder date until scheduled
E38: 0 | F38: =--(Tasks[[#This Row],[% COMPLETE]]>=1) -> 0
E39: 0 | F39: =--(Tasks[[#This Row],[% COMPLETE]]>=1) -> 0
E40: 0 | F40: =--(Tasks[[#This Row],[% COMPLETE]]>=1) -> 0
...

Sheet PilotData
B1: Location | C1: Label | D1: Sex | E1: Stomach weight (g) | F1: Gill weight (g) | G1: Date Dissected | H1: Comments | J1: Carapace length (bad data)
B2: WB (P) | C2: F,P,1 | D2: F | G2: 46067 | J2: 54.2
B3: P | C3: M,P,2 | D3: M | G3: 46067 | J3: 53.8
B4: P | C4: F,P,3 | D4: F | G4: 46067 | J4: 50.9
B5: P | C5: M,P,4 | D5: M | G5: 46067 | J5: 51
B6: P | C6: M,P,5 | D6: M | G6: 46067 | J6: 52.1
A7: Pooled samples | E7: ~1g | F7: <1g | H7: Pooled all stomach samples and all gill samples

Sheet Crab Data
A1: Location | B1: Label | C1: Sex | D1: Carapace length (mm) | E1: Net mass (test tube + stomach) (g) | F1: Empty test tube mass (g) | G1: Stomach weight (g) | H1: Date Dissected | I1: Date Digested | J1: Comments | K1: Urban | N1: Test tube + digestion sol'n | O1: Test tube | P1: Digestion sol'n
A2: TB | B2: F.TB.1 | C2: F | D2: 15.5 | E2: 6.2115 | F2: 6.1559 | G2: =E2-F2 -> 0.0556 | H2: 46055 | I2: 46059 | K2: URBAN | N2: 4.2354 | O2: 2.0486 | P2: =N2-O2 -> 2.1868
A3: TB | B3: M.TB.2 | C3: M | D3: 17.9 | E3: 6.1195 | F3: 6.0523 | G3: =E3-F3 -> 0.0672 | H3: 46055 | I3: 46059 | J3: Stomach maybe burst during weighing | K3: URBAN
A4: TB | B4: M.TB.3 | C4: M | D4: 18 | E4: 6.2014 | F4: 6.1331 | G4: =E4-F4 -> 0.0683 | H4: 46055 | I4: 46059 | J4: Stomach maybe burst during weighing | K4: URBAN
A5: TB | B5: M.TB.4 | C5: M | D5: 16.5 | E5: 6.2554 | F5: 6.1782 | G5: =E5-F5 -> 0.0772 | H5: 46055 | I5: 46059 | K5: URBAN
A6: TB | B6: F.TB.5 | C6: F | D6: 15.2 | E6: 6.1806 | F6: 6.1395 | G6: =E6-F6 -> 0.0411 | H6: 46055 | I6: 46059 | K6: URBAN
A7: TB | B7: M.TB.6 | C7: M | D7: 15.1 | E7: 6.3123 | F7: 6.2414 | G7: =E7-F7 -> 0.0709 | H7: 46055 | I7: 46059 | K7: URBAN
A8: TB | B8: M.TB.7 | C8: M | D8: 14.8 | E8: 6.3715 | F8: 6.2907 | G8: =E8-F8 -> 0.0808 | H8: 46055 | I8: 46059 | K8: URBAN
A9: TB | B9: F.TB.8 | C9: F | D9: 13.9 | E9: 6.4777 | F9: 6.41 | G9: =E9-F9 -> 0.0677 | H9: 46055 | I9: 46059 | K9: URBAN
A10: TB | B10: M.TB.9 | C10: M | D10: 16.7 | E10: 6.4745 | F10: 6.4097 | G10: =E10-F10 -> 0.0648 | H10: 46055 | I10: 46059 | K10: URBAN
A11: TB | B11: F.TB.10 | C11: F | D11: 15.8 | E11: 6.4292 | F11: 6.3581 | G11: =E11-F11 -> 0.0711 | H11: 46055 | I11: 46059 | K11: URBAN
A12: TB | B12: M.TB.11 | C12: M | D12: 17 | E12: 6.3299 | F12: 6.2315 | G12: =E12-F12 -> 0.0984 | H12: 46056 | I12: 46059 | J12: Caliper measurement is not the same as disection kit "ruler" gonna have to do some funky stuff | K12: URBAN
A13: TB | B13: M.TB.12 | C13: M | D13: 14.3 | E13: 6.3577 | F13: 6.2901 | G13: =E13-F13 -> 0.0676 | H13: 46056 | I13: 46059 | J13: Lowk mightve broken stomach… easier when still a bit frozen (in hindsight I don’t think I broke the stomach) | K13: URBAN
A14: TB | B14: F.TB.13 | C14: F | D14: 16.1 | E14: 6.5093 | F14: 6.4509 | G14: =E14-F14 -> 0.0584 | H14: 46056 | I14: 46059 | K14: URBAN
A15: TB | B15: F.TB.14 | C15: F | D15: 16.9 | E15: 6.3219 | F15: 6.2626 | G15: =E15-F15 -> 0.0593 | H15: 46056 | I15: 46059 | K15: URBAN
A16: TB | B16: F.TB.15 | C16: F | D16: 12.4 | E16: 6.2937 | F16: 6.2666 | G16: =E16-F16 -> 0.0271 | H16: 46056 | I16: 46059 | J16: Tiny one from when we were trying to leave the beach ASAP because of Coyote | K16: URBAN
A17: TB | B17: F.TB.16 | C17: F | D17: 15.9 | E17: 6.2683 | F17: 6.2341 | G17: =E17-F17 -> 0.0342 | H17: 46056 | I17: 46059 | J17: sometimes easier to take the "teeth" out and stomach comes with | K17: URBAN
A18: TB | B18: M.TB.17 | C18: M | D18: 17 | E18: 6.1841 | F18: 6.1149 | G18: =E18-F18 -> 0.0692 | H18: 46056 | I18: 46059 | K18: URBAN
A19: TB | B19: F.TB.18 | C19: F | D19: 16.2 | E19: 6.3521 | F19: 6.2853 | G19: =E19-F19 -> 0.0668 | H19: 46056 | I19: 46059 | K19: URBAN
A20: TB | B20: M.TB.19 | C20: M | D20: 14.9 | E20: 6.2643 | F20: 6.2081 | G20: =E20-F20 -> 0.0562 | H20: 46056 | I20: 46059 | K20: URBAN
A21: TB | B21: F.TB.20 | C21: F | D21: 17 | E21: 6.3311 | F21: 6.279 | G21: =E21-F21 -> 0.0521 | H21: 46056 | I21: 46059 | J21: Measured with C to F converter bc no caliper | K21: URBAN
A22: KB | B22: M.KB.1 | C22: M | D22: 14.6 | E22: =18.4603-2.05 -> 16.4103 | F22: 16.3662 | G22: =E22-F22 -> 0.0441 | H22: 46064 | I22: 46064 | J22: All below weighed with caps on; MKB 1-5 weird ? weighed with digestion sol'n in tube and subtracted estimated digestion sol'n weight (~2.1 pm 0.05 g) | K22: URBAN
A23: KB | B23: M.KB.2 | C23: M | D23: 14.2 | E23: =16.7166-2.1 -> 14.6166 | F23: 14.5712 | G23: =E23-F23 -> 0.0454 | H23: 46064 | I23: 46064 | J23: Weird | K23: URBAN
A24: KB | B24: M.KB.3 | C24: M | D24: 12.1 | E24: =18.7153-2.1 -> 16.6153 | F24: 16.5944 | G24: =E24-F24 -> 0.0209 | H24: 46064 | I24: 46064 | J24: Weird | K24: URBAN
A25: KB | B25: M.KB.4 | C25: M | D25: 16.1 | E25: =18.5491-2.1 -> 16.4491 | F25: 16.3952 | G25: =E25-F25 -> 0.0539 | H25: 46064 | I25: 46064 | J25: Weird | K25: URBAN
A26: KB | B26: M.KB.5 | C26: M | D26: 12.4 | E26: =17.7338-P2 -> 15.547 | F26: 15.5353 | G26: =E26-F26 -> 0.0117 | H26: 46064 | I26: 46064 | J26: Weird | K26: URBAN
A27: KB | B27: M.KB.6 | C27: M | D27: 13.3 | E27: 16.4534 | F27: 16.409 | G27: =E27-F27 -> 0.0444 | H27: 46064 | I27: 46069 | K27: URBAN
A28: KB | B28: M.KB.7 | C28: M | D28: 12 | E28: 15.0852 | F28: 15.0635 | G28: =E28-F28 -> 0.0217 | H28: 46064 | I28: 46069 | K28: URBAN
A29: KB | B29: M.KB.8 | C29: M | D29: 12.5 | E29: 15.1443 | F29: 15.1028 | G29: =E29-F29 -> 0.0415 | H29: 46064 | I29: 46069 | K29: URBAN
A30: KB | B30: M.KB.9 | C30: M | D30: 12.2 | E30: 15.6258 | F30: 15.5998 | G30: =E30-F30 -> 0.026 | H30: 46064 | I30: 46069 | K30: URBAN
A31: KB | B31: M.KB.10 | C31: M | D31: 16.5 | E31: 15.2341 | F31: 15.1846 | G31: =E31-F31 -> 0.0495 | H31: 46064 | I31: 46069 | K31: URBAN
A32: KB | B32: F.KB.11 | C32: F | D32: 19.1 | E32: 16.5037 | F32: 16.414 | G32: =E32-F32 -> 0.0897 | H32: 46064 | I32: 46069 | K32: URBAN
A33: KB | B33: F.KB.12 | C33: F | D33: 13.9 | E33: 16.5788 | F33: 16.5253 | G33: =E33-F33 -> 0.0535 | H33: 46064 | I33: 46069 | K33: URBAN
A34: KB | B34: F.KB.13 | C34: F | D34: 15 | E34: 16.3354 | F34: 16.2989 | G34: =E34-F34 -> 0.0365 | H34: 46064 | I34: 46069 | K34: URBAN
A35: KB | B35: F.KB.14 | C35: F | D35: 13 | E35: 15.4316 | F35: 15.3691 | G35: =E35-F35 -> 0.0625 | H35: 46064 | I35: 46069 | K35: URBAN
A36: KB | B36: F.KB.15 | C36: F | D36: 13.1 | E36: 16.1787 | F36: 16.1743 | G36: =E36-F36 -> 0.0044 | H36: 46064 | I36: 46069 | K36: URBAN
A37: KB | B37: F.KB.16 | C37: F | D37: 14.6 | E37: 16.6155 | F37: 16.5784 | G37: =E37-F37 -> 0.0371 | H37: 46064 | I37: 46069 | K37: URBAN
A38: KB | B38: F.KB.17 | C38: F | D38: 17.5 | E38: 16.3296 | F38: 16.2832 | G38: =E38-F38 -> 0.0464 | H38: 46064 | I38: 46069 | K38: URBAN
... A42: EB | B42: M.EB.1 | C42: M | D42: 14.6 | E42: 6.0343 | F42: 6.0083 | G42: =E42-F42 -> 0.026 | H42: 46072 | I42: 46075 | K42: URBAN
A43: EB | B43: M.EB.2 | C43: M | D43: 15.8 | E43: 6.1076 | F43: 6.0579 | G43: =E43-F43 -> 0.0497 | H43: 46072 | I43: 46075 | J43: fell on the floor while weighing :( | K43: URBAN
...

Sheet MPData
A1: {='Crab Data'!A1:A121} -> Location | B1: {='Crab Data'!B1:B121} -> Label | C1: {='Crab Data'!C1:C121} -> Sex | D1: {='Crab Data'!G1:G121} -> Stomach weight (g) | E1: Date analyzed | F1: Total.SMP.Per.Crab | G1: Total[SMP] (p/g) | H1: Rated.3.SMP.Per.Crab | I1: Rated.3.[SMP] (p/g) | J1: Rated.2.SMP.Per.Crab | K1: Rated.2.[SMP] (p/g) | L1: Rated.1.SMP.Per.Crab | M1: Rated.1.[SMP] (p/g) | N1: {='Crab Data'!K1:K121} -> Urban | O1: Distance.Rank | P1: Comments
A2: TB | B2: F.TB.1 | C2: F | D2: 0.0556 | E2: 46069 | F2: 8 | G2: =QUOTIENT(F2,D2) -> 143 | H2: 4 | I2: =QUOTIENT(H2,D2) -> 71 | J2: 2 | K2: =QUOTIENT(J2,D2) -> 35 | L2: 2 | M2: =QUOTIENT(L2,D2) -> 35 | N2: URBAN | O2: 1
A3: TB | B3: M.TB.2 | C3: M | D3: 0.0672 | E3: 46069 | F3: 3 | G3: =QUOTIENT(F3,D3) -> 44 | H3: 2 | I3: =QUOTIENT(H3,D3) -> 29 | J3: 1 | K3: =QUOTIENT(J3,D3) -> 14 | L3: 0 | M3: =QUOTIENT(L3,D3) -> 0 | N3: URBAN | O3: 1
A4: TB | B4: M.TB.3 | C4: M | D4: 0.0683 | E4: 46069 | F4: 4 | G4: =QUOTIENT(F4,D4) -> 58 | H4: 2 | I4: =QUOTIENT(H4,D4) -> 29 | J4: 1 | K4: =QUOTIENT(J4,D4) -> 14 | L4: 1 | M4: =QUOTIENT(L4,D4) -> 14 | N4: URBAN | O4: 1
A5: TB | B5: M.TB.4 | C5: M | D5: 0.0772 | E5: 46069 | F5: 7 | G5: =QUOTIENT(F5,D5) -> 90 | H5: 3 | I5: =QUOTIENT(H5,D5) -> 38 | J5: 4 | K5: =QUOTIENT(J5,D5) -> 51 | L5: 0 | M5: =QUOTIENT(L5,D5) -> 0 | N5: URBAN | O5: 1 | P5: a large ball of black and clear plastic fibres was found, smaller black fragments are likely from this ball
A6: TB | B6: F.TB.5 | C6: F | D6: 0.0411 | E6: 46069 | F6: 3 | G6: =QUOTIENT(F6,D6) -> 72 | H6: 1 | I6: =QUOTIENT(H6,D6) -> 24 | J6: 2 | K6: =QUOTIENT(J6,D6) -> 48 | L6: 0 | M6: =QUOTIENT(L6,D6) -> 0 | N6: URBAN | O6: 1
A7: TB | B7: M.TB.6 | C7: M | D7: 0.0709 | E7: 46069 | F7: 5 | G7: =QUOTIENT(F7,D7) -> 70 | H7: 4 | I7: =QUOTIENT(H7,D7) -> 56 | J7: 0 | K7: =QUOTIENT(J7,D7) -> 0 | L7: 1 | M7: =QUOTIENT(L7,D7) -> 14 | N7: URBAN | O7: 1
A8: TB | B8: M.TB.7 | C8: M | D8: 0.0808 | E8: 46069 | F8: 21 | G8: =QUOTIENT(F8,D8) -> 259 | H8: 7 | I8: =QUOTIENT(H8,D8) -> 86 | J8: 8 | K8: =QUOTIENT(J8,D8) -> 99 | L8: 6 | M8: =QUOTIENT(L8,D8) -> 74 | N8: URBAN | O8: 1
A9: TB | B9: F.TB.8 | C9: F | D9: 0.0677 | E9: 46069 | F9: 13 | G9: =QUOTIENT(F9,D9) -> 192 | H9: 5 | I9: =QUOTIENT(H9,D9) -> 73 | J9: 6 | K9: =QUOTIENT(J9,D9) -> 88 | L9: 2 | M9: =QUOTIENT(L9,D9) -> 29 | N9: URBAN | O9: 1
A10: TB | B10: M.TB.9 | C10: M | D10: 0.0648 | E10: 46069 | F10: 4 | G10: =QUOTIENT(F10,D10) -> 61 | H10: 0 | I10: =QUOTIENT(H10,D10) -> 0 | J10: 3 | K10: =QUOTIENT(J10,D10) -> 46 | L10: 1 | M10: =QUOTIENT(L10,D10) -> 15 | N10: URBAN | O10: 1
A11: TB | B11: F.TB.10 | C11: F | D11: 0.0711 | E11: 46069 | F11: 5 | G11: =QUOTIENT(F11,D11) -> 70 | H11: 3 | I11: =QUOTIENT(H11,D11) -> 42 | J11: 2 | K11: =QUOTIENT(J11,D11) -> 28 | M11: =QUOTIENT(L11,D11) -> 0 | N11: URBAN | O11: 1 | P11: big honkin fibre in this boy
A12: TB | B12: M.TB.11 | C12: M | D12: 0.0984 | E12: 46069 | F12: 11 | G12: =QUOTIENT(F12,D12) -> 111 | H12: 5 | I12: =QUOTIENT(H12,D12) -> 50 | J12: 2 | K12: =QUOTIENT(J12,D12) -> 20 | L12: 4 | M12: =QUOTIENT(L12,D12) -> 40 | N12: URBAN | O12: 1
A13: TB | B13: M.TB.12 | C13: M | D13: 0.0676 | E13: 46069 | F13: 13 | G13: =QUOTIENT(F13,D13) -> 192 | H13: 2 | I13: =QUOTIENT(H13,D13) -> 29 | J13: 9 | K13: =QUOTIENT(J13,D13) -> 133 | L13: 2 | M13: =QUOTIENT(L13,D13) -> 29 | N13: URBAN | O13: 1
A14: TB | B14: F.TB.13 | C14: F | D14: 0.0584 | E14: 46069 | F14: 5 | G14: =QUOTIENT(F14,D14) -> 85 | H14: 0 | I14: =QUOTIENT(H14,D14) -> 0 | J14: 2 | K14: =QUOTIENT(J14,D14) -> 34 | L14: 3 | M14: =QUOTIENT(L14,D14) -> 51 | N14: URBAN | O14: 1
A15: TB | B15: F.TB.14 | C15: F | D15: 0.0593 | E15: 46069 | F15: 4 | G15: =QUOTIENT(F15,D15) -> 67 | H15: 0 | I15: =QUOTIENT(H15,D15) -> 0 | J15: 2 | K15: =QUOTIENT(J15,D15) -> 33 | L15: 2 | M15: =QUOTIENT(L15,D15) -> 33 | N15: URBAN | O15: 1
A16: TB | B16: F.TB.15 | C16: F | D16: 0.0271 | E16: 46069 | F16: 1 | G16: =QUOTIENT(F16,D16) -> 36 | H16: 1 | I16: =QUOTIENT(H16,D16) -> 36 | J16: 0 | K16: =QUOTIENT(J16,D16) -> 0 | L16: 0 | M16: =QUOTIENT(L16,D16) -> 0 | N16: URBAN | O16: 1 | P16: go back to this to double check
A17: TB | B17: F.TB.16 | C17: F | D17: 0.0342 | E17: 46069 | F17: 1 | G17: =QUOTIENT(F17,D17) -> 29 | H17: 0 | I17: =QUOTIENT(H17,D17) -> 0 | J17: 0 | K17: =QUOTIENT(J17,D17) -> 0 | L17: 1 | M17: =QUOTIENT(L17,D17) -> 29 | N17: URBAN | O17: 1
A18: TB | B18: M.TB.17 | C18: M | D18: 0.0692 | E18: 46070 | F18: 8 | G18: =QUOTIENT(F18,D18) -> 115 | H18: 1 | I18: =QUOTIENT(H18,D18) -> 14 | J18: 3 | K18: =QUOTIENT(J18,D18) -> 43 | L18: 4 | M18: =QUOTIENT(L18,D18) -> 57 | N18: URBAN | O18: 1
A19: TB | B19: F.TB.18 | C19: F | D19: 0.0668 | E19: 46070 | F19: 25 | G19: =QUOTIENT(F19,D19) -> 374 | H19: 8 | I19: =QUOTIENT(H19,D19) -> 119 | J19: 13 | K19: =QUOTIENT(J19,D19) -> 194 | L19: 4 | M19: =QUOTIENT(L19,D19) -> 59 | N19: URBAN | O19: 1 | P19: damn that’s a lot
A20: TB | B20: M.TB.19 | C20: M | D20: 0.0562 | E20: 46071 | F20: 3 | G20: =QUOTIENT(F20,D20) -> 53 | H20: 3 | I20: =QUOTIENT(H20,D20) -> 53 | J20: 0 | K20: =QUOTIENT(J20,D20) -> 0 | L20: 0 | M20: =QUOTIENT(L20,D20) -> 0 | N20: URBAN | O20: 1
A21: TB | B21: F.TB.20 | C21: F | D21: 0.0521 | E21: 46071 | F21: 4 | G21: =QUOTIENT(F21,D21) -> 76 | H21: 0 | I21: =QUOTIENT(H21,D21) -> 0 | J21: 1 | K21: =QUOTIENT(J21,D21) -> 19 | L21: 3 | M21: =QUOTIENT(L21,D21) -> 57 | N21: URBAN | O21: 1
A22: KB | B22: M.KB.1 | C22: M | D22: 0.0441 | E22: 46072 | F22: 13 | G22: =QUOTIENT(F22,D22) -> 294 | H22: 6 | I22: =QUOTIENT(H22,D22) -> 136 | J22: 5 | K22: =QUOTIENT(J22,D22) -> 113 | L22: 2 | M22: =QUOTIENT(L22,D22) -> 45 | N22: URBAN | O22: 2
A23: KB | B23: M.KB.2 | C23: M | D23: 0.0454 | E23: 46072 | F23: 5 | G23: =QUOTIENT(F23,D23) -> 110 | H23: 1 | I23: =QUOTIENT(H23,D23) -> 22 | J23: 3 | K23: =QUOTIENT(J23,D23) -> 66 | L23: 1 | M23: =QUOTIENT(L23,D23) -> 22 | N23: URBAN | O23: 2
A24: KB | B24: M.KB.3 | C24: M | D24: 0.0209 | E24: 46072 | F24: 4 | G24: =QUOTIENT(F24,D24) -> 191 | H24: 1 | I24: =QUOTIENT(H24,D24) -> 47 | J24: 0 | K24: =QUOTIENT(J24,D24) -> 0 | L24: 3 | M24: =QUOTIENT(L24,D24) -> 143 | N24: URBAN | O24: 2
A25: KB | B25: M.KB.4 | C25: M | D25: 0.0539 | E25: 46072 | F25: 2 | G25: =QUOTIENT(F25,D25) -> 37 | H25: 1 | I25: =QUOTIENT(H25,D25) -> 18 | J25: 0 | K25: =QUOTIENT(J25,D25) -> 0 | L25: 1 | M25: =QUOTIENT(L25,D25) -> 18 | N25: URBAN | O25: 2
A26: KB | B26: M.KB.5 | C26: M | D26: 0.0117 | E26: 46072 | F26: 2 | G26: =QUOTIENT(F26,D26) -> 170 | H26: 2 | I26: =QUOTIENT(H26,D26) -> 170 | J26: 0 | K26: =QUOTIENT(J26,D26) -> 0 | L26: 0 | M26: =QUOTIENT(L26,D26) -> 0 | N26: URBAN | O26: 2
A27: KB | B27: M.KB.6 | C27: M | D27: 0.0444 | E27: 46072 | F27: 5 | G27: =QUOTIENT(F27,D27) -> 112 | H27: 2 | I27: =QUOTIENT(H27,D27) -> 45 | J27: 2 | K27: =QUOTIENT(J27,D27) -> 45 | L27: 1 | M27: =QUOTIENT(L27,D27) -> 22 | N27: URBAN | O27: 2
A28: KB | B28: M.KB.7 | C28: M | D28: 0.0217 | E28: 46075 | F28: 19 | G28: =QUOTIENT(F28,D28) -> 875 | H28: 1 | I28: =QUOTIENT(H28,D28) -> 46 | J28: 8 | K28: =QUOTIENT(J28,D28) -> 368 | L28: 10 | M28: =QUOTIENT(L28,D28) -> 460 | N28: URBAN | O28: 2
A29: KB | B29: M.KB.8 | C29: M | D29: 0.0415 | E29: 46075 | F29: 11 | G29: =QUOTIENT(F29,D29) -> 265 | H29: 8 | I29: =QUOTIENT(H29,D29) -> 192 | J29: 1 | K29: =QUOTIENT(J29,D29) -> 24 | L29: 2 | M29: =QUOTIENT(L29,D29) -> 48 | N29: URBAN | O29: 2
A30: KB | B30: M.KB.9 | C30: M | D30: 0.026 | E30: 46075 | F30: 14 | G30: =QUOTIENT(F30,D30) -> 538 | H30: 5 | I30: =QUOTIENT(H30,D30) -> 192 | J30: 5 | K30: =QUOTIENT(J30,D30) -> 192 | L30: 4 | M30: =QUOTIENT(L30,D30) -> 153 | N30: URBAN | O30: 2
A31: KB | B31: M.KB.10 | C31: M | D31: 0.0495 | E31: 46075 | F31: 22 | G31: =QUOTIENT(F31,D31) -> 444 | H31: 10 | I31: =QUOTIENT(H31,D31) -> 202 | J31: 10 | K31: =QUOTIENT(J31,D31) -> 202 | L31: 2 | M31: =QUOTIENT(L31,D31) -> 40 | N31: URBAN | O31: 2
... A35: KB | B35: F.KB.14 | C35: F | D35: 0.0625 | E35: 46076 | F35: 5 | G35: =QUOTIENT(F35,D35) -> 80 | H35: 1 | I35: =QUOTIENT(H35,D35) -> 16 | J35: 0 | K35: =QUOTIENT(J35,D35) -> 0 | L35: 4 | M35: =QUOTIENT(L35,D35) -> 64 | N35: URBAN | O35: 2
A36: KB | B36: F.KB.15 | C36: F | D36: 0.0044 | E36: 46079 | F36: 8 | G36: =QUOTIENT(F36,D36) -> 1818 | H36: 6 | I36: =QUOTIENT(H36,D36) -> 1363 | J36: 1 | K36: =QUOTIENT(J36,D36) -> 227 | L36: 1 | M36: =QUOTIENT(L36,D36) -> 227 | N36: URBAN | O36: 2 | P36: Weird
A37: KB | B37: F.KB.16 | C37: F | D37: 0.0371 | E37: 46079 | F37: 10 | G37: =QUOTIENT(F37,D37) -> 269 | H37: 5 | I37: =QUOTIENT(H37,D37) -> 134 | J37: 2 | K37: =QUOTIENT(J37,D37) -> 53 | L37: 3 | M37: =QUOTIENT(L37,D37) -> 80 | N37: URBAN | O37: 2
A38: KB | B38: F.KB.17 | C38: F | D38: 0.0464 | E38: 46076 | F38: 4 | G38: =QUOTIENT(F38,D38) -> 86 | H38: 3 | I38: =QUOTIENT(H38,D38) -> 64 | J38: 0 | K38: =QUOTIENT(J38,D38) -> 0 | L38: 1 | M38: =QUOTIENT(L38,D38) -> 21 | N38: URBAN | O38: 2
A39: KB | B39: F.KB.18 | C39: F | D39: 0.038 | E39: 46080 | F39: 9 | G39: =QUOTIENT(F39,D39) -> 236 | H39: 4 | I39: =QUOTIENT(H39,D39) -> 105 | J39: 1 | K39: =QUOTIENT(J39,D39) -> 26 | L39: 4 | M39: =QUOTIENT(L39,D39) -> 105 | N39: URBAN | O39: 2
A40: KB | B40: F.KB.19 | C40: F | D40: 0.0167 | E40: 46080 | F40: 6 | G40: =QUOTIENT(F40,D40) -> 359 | H40: 1 | I40: =QUOTIENT(H40,D40) -> 59 | J40: 3 | K40: =QUOTIENT(J40,D40) -> 179 | L40: 2 | M40: =QUOTIENT(L40,D40) -> 119 | N40: URBAN | O40: 2
A41: KB | B41: F.KB.20 | C41: F | D41: 0.036 | E41: 46080 | F41: 5 | G41: =QUOTIENT(F41,D41) -> 138 | H41: 0 | I41: =QUOTIENT(H41,D41) -> 0 | J41: 0 | K41: =QUOTIENT(J41,D41) -> 0 | L41: 5 | M41: =QUOTIENT(L41,D41) -> 138 | N41: URBAN | O41: 2
A42: EB | B42: M.EB.1 | C42: M | D42: 0.026 | E42: 46080 | F42: 23 | G42: =QUOTIENT(F42,D42) -> 884 | H42: 8 | I42: =QUOTIENT(H42,D42) -> 307 | J42: 10 | K42: =QUOTIENT(J42,D42) -> 384 | L42: 5 | M42: =QUOTIENT(L42,D42) -> 192 | N42: URBAN | O42: 3
A43: EB | B43: M.EB.2 | C43: M | D43: 0.0497 | E43: 46080 | F43: 8 | G43: =QUOTIENT(F43,D43) -> 160 | H43: 6 | I43: =QUOTIENT(H43,D43) -> 120 | J43: 2 | K43: =QUOTIENT(J43,D43) -> 40 | L43: 0 | M43: =QUOTIENT(L43,D43) -> 0 | N43: URBAN | O43: 3
...

Sheet calcs
A1: *** This sheet should remain hidden ***
C3: Today: | D3: =TODAY() -> 46102
D4: 5
C5: # of rows | D5: =ROWS(Activities[]) -> 22
E6: =NA() -> #N/A
E7: =NA() -> #N/A
E8: =NA() -> #N/A
C9: Window Activities: | D9: =SUMPRODUCT( ((Activities[Start]>=StartDateWindow)+(Activities[End]>=StartDateWindow)>0)*(Activities[Start]<=(StartDateWindow+WindowDays-1)) ) -> 6 | E9: =NA() -> #N/A
D10: 9 | E10: =NA() -> #N/A
D11: =D10-MIN(D10,D9) -> 3 | E11: =NA() -> #N/A
E12: =NA() -> #N/A
E13: =NA() -> #N/A
E14: =NA() -> #N/A
E15: {=INDEX(Activities[Id],MATCH(1, ((Activities[Start]>=StartDateWindow)+(Activities[End]>=StartDateWindow)>0)*(Activities[Start]<=(StartDateWindow+WindowDays-1)), 0))} -> -5 | F15: =OFFSET(E15,-$D$11,) -> #N/A
E16: {=INDEX(Activities[Id],MATCH(1, (Activities[Id]>E15)*((Activities[Start]>=StartDateWindow)+(Activities[End]>=StartDateWindow)>0)*(Activities[Start]<=(StartDateWindow+WindowDays-1)), 0))} -> -4 | F16: =OFFSET(E16,-$D$11,) -> #N/A
E17: {=INDEX(Activities[Id],MATCH(1, (Activities[Id]>E16)*((Activities[Start]>=StartDateWindow)+(Activities[End]>=StartDateWindow)>0)*(Activities[Start]<=(StartDateWindow+WindowDays-1)), 0))} -> -3 | F17: =OFFSET(E17,-$D$11,) -> #N/A
E18: {=INDEX(Activities[Id],MATCH(1, (Activities[Id]>E17)*((Activities[Start]>=StartDateWindow)+(Activities[End]>=StartDateWindow)>0)*(Activities[Start]<=(StartDateWindow+WindowDays-1)), 0))} -> -2 | F18: =OFFSET(E18,-$D$11,) -> -5
E19: {=INDEX(Activities[Id],MATCH(1, (Activities[Id]>E18)*((Activities[Start]>=StartDateWindow)+(Activities[End]>=StartDateWindow)>0)*(Activities[Start]<=(StartDateWindow+WindowDays-1)), 0))} -> 0 | F19: =OFFSET(E19,-$D$11,) -> -4
E20: {=INDEX(Activities[Id],MATCH(1, (Activities[Id]>E19)*((Activities[Start]>=StartDateWindow)+(Activities[End]>=StartDateWindow)>0)*(Activities[Start]<=(StartDateWindow+WindowDays-1)), 0))} -> 1 | F20: =OFFSET(E20,-$D$11,) -> -3
E21: {=INDEX(Activities[Id],MATCH(1, (Activities[Id]>E20)*((Activities[Start]>=StartDateWindow)+(Activities[End]>=StartDateWindow)>0)*(Activities[Start]<=(StartDateWindow+WindowDays-1)), 0))} -> #N/A | F21: =OFFSET(E21,-$D$11,) -> -2
E22: {=INDEX(Activities[Id],MATCH(1, (Activities[Id]>E21)*((Activities[Start]>=StartDateWindow)+(Activities[End]>=StartDateWindow)>0)*(Activities[Start]<=(StartDateWindow+WindowDays-1)), 0))} -> #N/A | F22: =OFFSET(E22,-$D$11,) -> 0
E23: {=INDEX(Activities[Id],MATCH(1, (Activities[Id]>E22)*((Activities[Start]>=StartDateWindow)+(Activities[End]>=StartDateWindow)>0)*(Activities[Start]<=(StartDateWindow+WindowDays-1)), 0))} -> #N/A | F23: =OFFSET(E23,-$D$11,) -> 1
C25: Calc Window Start | D25: =StartDate+WindowOffset -> 46076
C26: Offset | D26: 84
C28: Start | D28: ='Project timeline'!F2 -> 45992
C29: Window | D29: 30
A31: Position | B31: Series | C31: Activity Id | D31: Activity | E31: =StartDateWindow -> 46076 | F31: =E31+1 -> 46077 | G31: =F31+1 -> 46078 | H31: =G31+1 -> 46079 | I31: =H31+1 -> 46080 | J31: =I31+1 -> 46081 | K31: =J31+1 -> 46082 | L31: =K31+1 -> 46083 | M31: =L31+1 -> 46084 | ... AI31: =AH31+1 -> 46106
A32: 11.3 | B32: 1 | C32: =F15 -> #N/A | D32: =INDEX(Activities[[Deadline ]],MATCH($C32,Activities[Id],0)) -> #N/A | E32: =GridCalc -> #N/A | F32: =GridCalc -> #N/A | G32: =GridCalc -> #N/A | H32: =GridCalc -> #N/A | I32: =GridCalc -> #N/A | J32: =GridCalc -> #N/A | K32: =GridCalc -> #N/A | L32: =GridCalc -> #N/A | ... AI32: =GridCalc -> #N/A
A33: =A32-1 -> 10.3 | B33: 2 | C33: =F16 -> #N/A | D33: =INDEX(Activities[[Deadline ]],MATCH($C33,Activities[Id],0)) -> #N/A | E33: =GridCalc -> #N/A | F33: =GridCalc -> #N/A | G33: =GridCalc -> #N/A | H33: =GridCalc -> #N/A | I33: =GridCalc -> #N/A | J33: =GridCalc -> #N/A | K33: =GridCalc -> #N/A | L33: =GridCalc -> #N/A | ... AI33: =GridCalc -> #N/A
A34: =A33-1 -> 9.3 | B34: 3 | C34: =F17 -> #N/A | D34: =INDEX(Activities[[Deadline ]],MATCH($C34,Activities[Id],0)) -> #N/A | E34: =GridCalc -> #N/A | F34: =GridCalc -> #N/A | G34: =GridCalc -> #N/A | H34: =GridCalc -> #N/A | I34: =GridCalc -> #N/A | J34: =GridCalc -> #N/A | K34: =GridCalc -> #N/A | L34: =GridCalc -> #N/A | ... AI34: =GridCalc -> #N/A
A35: =A34-1 -> 8.3 | B35: 4 | C35: =F18 -> -5 | D35: =INDEX(Activities[[Deadline ]],MATCH($C35,Activities[Id],0)) -> Methods and data analysis due | E35: =GridCalc -> #N/A | F35: =GridCalc -> #N/A | G35: =GridCalc -> 8.3 | H35: =GridCalc -> 8.3 | I35: =GridCalc -> 8.3 | J35: =GridCalc -> 8.3 | K35: =GridCalc -> 8.3 | L35: =GridCalc -> 8.3 | ... AI35: =GridCalc -> #N/A
A36: =A35-1 -> 7.3 | B36: 5 | C36: =F19 -> -4 | D36: =INDEX(Activities[[Deadline ]],MATCH($C36,Activities[Id],0)) -> Formal round table meeting with mentor | E36: =GridCalc -> 7.3 | F36: =GridCalc -> 7.3 | G36: =GridCalc -> 7.3 | H36: =GridCalc -> 7.3 | I36: =GridCalc -> 7.3 | J36: =GridCalc -> #N/A | K36: =GridCalc -> #N/A | L36: =GridCalc -> #N/A | ... AI36: =GridCalc -> #N/A
A37: =A36-1 -> 6.3 | B37: 6 | C37: =F20 -> -3 | D37: =INDEX(Activities[[Deadline ]],MATCH($C37,Activities[Id],0)) -> STAGE THREE | E37: =GridCalc -> 6.3 | F37: =GridCalc -> #N/A | G37: =GridCalc -> #N/A | H37: =GridCalc -> #N/A | I37: =GridCalc -> #N/A | J37: =GridCalc -> #N/A | K37: =GridCalc -> #N/A | L37: =GridCalc -> #N/A | ... AI37: =GridCalc -> #N/A
A38: =A37-1 -> 5.3 | B38: 7 | C38: =F21 -> -2 | D38: =INDEX(Activities[[Deadline ]],MATCH($C38,Activities[Id],0)) -> Initial report due for peer review | E38: =GridCalc -> #N/A | F38: =GridCalc -> #N/A | G38: =GridCalc -> #N/A | H38: =GridCalc -> #N/A | I38: =GridCalc -> #N/A | J38: =GridCalc -> #N/A | K38: =GridCalc -> #N/A | L38: =GridCalc -> #N/A | ... AI38: =GridCalc -> #N/A
A39: =A38-1 -> 4.3 | B39: 8 | C39: =F22 -> 0 | D39: =INDEX(Activities[[Deadline ]],MATCH($C39,Activities[Id],0)) -> Conference abstract due | E39: =GridCalc -> #N/A | F39: =GridCalc -> #N/A | G39: =GridCalc -> #N/A | H39: =GridCalc -> #N/A | I39: =GridCalc -> #N/A | J39: =GridCalc -> #N/A | K39: =GridCalc -> #N/A | L39: =GridCalc -> #N/A | ... AI39: =GridCalc -> #N/A
A40: =A39-1 -> 3.3 | B40: 9 | C40: =F23 -> 1 | D40: =INDEX(Activities[[Deadline ]],MATCH($C40,Activities[Id],0)) -> Check in with mentor | E40: =GridCalc -> #N/A | F40: =GridCalc -> #N/A | G40: =GridCalc -> #N/A | H40: =GridCalc -> #N/A | I40: =GridCalc -> #N/A | J40: =GridCalc -> #N/A | K40: =GridCalc -> #N/A | L40: =GridCalc -> #N/A | ... AI40: =GridCalc -> #N/A
E43: =E31 -> 46076 | F43: =F31 -> 46077 | G43: =G31 -> 46078 | H43: =H31 -> 46079 | I43: =I31 -> 46080 | J43: =J31 -> 46081 | K43: =K31 -> 46082 | L43: =L31 -> 46083 | ... AH43: =AH31 -> 46105
C44: =C32 -> #N/A | D44: =UPPER(INDEX(Activities[[Deadline ]],MATCH($C44,Activities[Id],0))) -> #N/A | E44: =IF(ISERROR(F32),E32,NA()) -> #N/A | F44: =IF(ISERROR(G32),F32,NA()) -> #N/A | G44: =IF(ISERROR(H32),G32,NA()) -> #N/A | H44: =IF(ISERROR(I32),H32,NA()) -> #N/A | I44: =IF(ISERROR(J32),I32,NA()) -> #N/A | J44: =IF(ISERROR(K32),J32,NA()) -> #N/A | K44: =IF(ISERROR(L32),K32,NA()) -> #N/A | L44: =IF(ISERROR(M32),L32,NA()) -> #N/A | ... AH44: =IF(ISERROR(AI32),AH32,NA()) -> #N/A
C45: =C33 -> #N/A | D45: =UPPER(INDEX(Activities[[Deadline ]],MATCH($C45,Activities[Id],0))) -> #N/A | E45: =IF(ISERROR(F33),E33,NA()) -> #N/A | F45: =IF(ISERROR(G33),F33,NA()) -> #N/A | G45: =IF(ISERROR(H33),G33,NA()) -> #N/A | H45: =IF(ISERROR(I33),H33,NA()) -> #N/A | I45: =IF(ISERROR(J33),I33,NA()) -> #N/A | J45: =IF(ISERROR(K33),J33,NA()) -> #N/A | K45: =IF(ISERROR(L33),K33,NA()) -> #N/A | L45: =IF(ISERROR(M33),L33,NA()) -> #N/A | ... AH45: =IF(ISERROR(AI33),AH33,NA()) -> #N/A
C46: =C34 -> #N/A | D46: =UPPER(INDEX(Activities[[Deadline ]],MATCH($C46,Activities[Id],0))) -> #N/A | E46: =IF(ISERROR(F34),E34,NA()) -> #N/A | F46: =IF(ISERROR(G34),F34,NA()) -> #N/A | G46: =IF(ISERROR(H34),G34,NA()) -> #N/A | H46: =IF(ISERROR(I34),H34,NA()) -> #N/A | I46: =IF(ISERROR(J34),I34,NA()) -> #N/A | J46: =IF(ISERROR(K34),J34,NA()) -> #N/A | K46: =IF(ISERROR(L34),K34,NA()) -> #N/A | L46: =IF(ISERROR(M34),L34,NA()) -> #N/A | ... AH46: =IF(ISERROR(AI34),AH34,NA()) -> #N/A
...
